Workbook

Sheet Dashboard
A1: YES24 도서 데이터 요약 대시보드
A3: 총 도서 등록 수 | C3: 평균 도서 판매가 | E3: 평균 도서 할인율 | G3: 도서 누적 판매지수 | I3: 도서 누적 리뷰 수 | K3: ※ 참고 사항: 본 대시보드는 실시간 수식 연동형으로 구성되었습니다. 수식 결과는 검은색, 타 시트 참조 수식은 녹색, 수동 하드코딩 입력값은 파란색으로 표시되어 있습니다.
A4: =COUNT(Raw_Data!A2:A1201) | C4: =AVERAGE(Raw_Data!F2:F1201) | E4: =AVERAGE(Raw_Data!K2:K1201) | G4: =SUM(Raw_Data!H2:H1201) | I4: =SUM(Raw_Data!G2:G1201)
A6: ■ 주요 출판사별 요약 테이블 (Top 15) | I6: ■ 연도별 도서 발행 추이 요약 테이블
A7: 출판사 | B7: 도서 수 | C7: 평균 정가 | D7: 평균 판매가 | E7: 평균 할인율 | F7: 판매지수 합계 | G7: 리뷰 수 합계 | I7: 발행연도 | J7: 도서 수 | K7: 평균 정가 | L7: 평균 판매가 | M7: 평균 할인율 | N7: 판매지수 합계 | O7: 리뷰 수 합계
A8: =Analysis_Data!I2 | B8: =Analysis_Data!J2 | C8: =Analysis_Data!K2 | D8: =Analysis_Data!L2 | E8: =Analysis_Data!M2 | F8: =Analysis_Data!N2 | G8: =Analysis_Data!O2 | I8: =Analysis_Data!A2 | J8: =Analysis_Data!B2 | K8: =Analysis_Data!C2 | L8: =Analysis_Data!D2 | M8: =Analysis_Data!E2 | N8: =Analysis_Data!F2 | O8: =Analysis_Data!G2
A9: =Analysis_Data!I3 | B9: =Analysis_Data!J3 | C9: =Analysis_Data!K3 | D9: =Analysis_Data!L3 | E9: =Analysis_Data!M3 | F9: =Analysis_Data!N3 | G9: =Analysis_Data!O3 | I9: =Analysis_Data!A3 | J9: =Analysis_Data!B3 | K9: =Analysis_Data!C3 | L9: =Analysis_Data!D3 | M9: =Analysis_Data!E3 | N9: =Analysis_Data!F3 | O9: =Analysis_Data!G3
A10: =Analysis_Data!I4 | B10: =Analysis_Data!J4 | C10: =Analysis_Data!K4 | D10: =Analysis_Data!L4 | E10: =Analysis_Data!M4 | F10: =Analysis_Data!N4 | G10: =Analysis_Data!O4 | I10: =Analysis_Data!A4 | J10: =Analysis_Data!B4 | K10: =Analysis_Data!C4 | L10: =Analysis_Data!D4 | M10: =Analysis_Data!E4 | N10: =Analysis_Data!F4 | O10: =Analysis_Data!G4
A11: =Analysis_Data!I5 | B11: =Analysis_Data!J5 | C11: =Analysis_Data!K5 | D11: =Analysis_Data!L5 | E11: =Analysis_Data!M5 | F11: =Analysis_Data!N5 | G11: =Analysis_Data!O5 | I11: =Analysis_Data!A5 | J11: =Analysis_Data!B5 | K11: =Analysis_Data!C5 | L11: =Analysis_Data!D5 | M11: =Analysis_Data!E5 | N11: =Analysis_Data!F5 | O11: =Analysis_Data!G5
A12: =Analysis_Data!I6 | B12: =Analysis_Data!J6 | C12: =Analysis_Data!K6 | D12: =Analysis_Data!L6 | E12: =Analysis_Data!M6 | F12: =Analysis_Data!N6 | G12: =Analysis_Data!O6 | I12: =Analysis_Data!A6 | J12: =Analysis_Data!B6 | K12: =Analysis_Data!C6 | L12: =Analysis_Data!D6 | M12: =Analysis_Data!E6 | N12: =Analysis_Data!F6 | O12: =Analysis_Data!G6
A13: =Analysis_Data!I7 | B13: =Analysis_Data!J7 | C13: =Analysis_Data!K7 | D13: =Analysis_Data!L7 | E13: =Analysis_Data!M7 | F13: =Analysis_Data!N7 | G13: =Analysis_Data!O7 | I13: =Analysis_Data!A7 | J13: =Analysis_Data!B7 | K13: =Analysis_Data!C7 | L13: =Analysis_Data!D7 | M13: =Analysis_Data!E7 | N13: =Analysis_Data!F7 | O13: =Analysis_Data!G7
A14: =Analysis_Data!I8 | B14: =Analysis_Data!J8 | C14: =Analysis_Data!K8 | D14: =Analysis_Data!L8 | E14: =Analysis_Data!M8 | F14: =Analysis_Data!N8 | G14: =Analysis_Data!O8 | I14: =Analysis_Data!A8 | J14: =Analysis_Data!B8 | K14: =Analysis_Data!C8 | L14: =Analysis_Data!D8 | M14: =Analysis_Data!E8 | N14: =Analysis_Data!F8 | O14: =Analysis_Data!G8
A15: =Analysis_Data!I9 | B15: =Analysis_Data!J9 | C15: =Analysis_Data!K9 | D15: =Analysis_Data!L9 | E15: =Analysis_Data!M9 | F15: =Analysis_Data!N9 | G15: =Analysis_Data!O9 | I15: =Analysis_Data!A9 | J15: =Analysis_Data!B9 | K15: =Analysis_Data!C9 | L15: =Analysis_Data!D9 | M15: =Analysis_Data!E9 | N15: =Analysis_Data!F9 | O15: =Analysis_Data!G9
A16: =Analysis_Data!I10 | B16: =Analysis_Data!J10 | C16: =Analysis_Data!K10 | D16: =Analysis_Data!L10 | E16: =Analysis_Data!M10 | F16: =Analysis_Data!N10 | G16: =Analysis_Data!O10 | I16: =Analysis_Data!A10 | J16: =Analysis_Data!B10 | K16: =Analysis_Data!C10 | L16: =Analysis_Data!D10 | M16: =Analysis_Data!E10 | N16: =Analysis_Data!F10 | O16: =Analysis_Data!G10
A17: =Analysis_Data!I11 | B17: =Analysis_Data!J11 | C17: =Analysis_Data!K11 | D17: =Analysis_Data!L11 | E17: =Analysis_Data!M11 | F17: =Analysis_Data!N11 | G17: =Analysis_Data!O11 | I17: =Analysis_Data!A11 | J17: =Analysis_Data!B11 | K17: =Analysis_Data!C11 | L17: =Analysis_Data!D11 | M17: =Analysis_Data!E11 | N17: =Analysis_Data!F11 | O17: =Analysis_Data!G11
A18: =Analysis_Data!I12 | B18: =Analysis_Data!J12 | C18: =Analysis_Data!K12 | D18: =Analysis_Data!L12 | E18: =Analysis_Data!M12 | F18: =Analysis_Data!N12 | G18: =Analysis_Data!O12 | I18: =Analysis_Data!A12 | J18: =Analysis_Data!B12 | K18: =Analysis_Data!C12 | L18: =Analysis_Data!D12 | M18: =Analysis_Data!E12 | N18: =Analysis_Data!F12 | O18: =Analysis_Data!G12
A19: =Analysis_Data!I13 | B19: =Analysis_Data!J13 | C19: =Analysis_Data!K13 | D19: =Analysis_Data!L13 | E19: =Analysis_Data!M13 | F19: =Analysis_Data!N13 | G19: =Analysis_Data!O13 | I19: =Analysis_Data!A13 | J19: =Analysis_Data!B13 | K19: =Analysis_Data!C13 | L19: =Analysis_Data!D13 | M19: =Analysis_Data!E13 | N19: =Analysis_Data!F13 | O19: =Analysis_Data!G13
... A21: =Analysis_Data!I15 | B21: =Analysis_Data!J15 | C21: =Analysis_Data!K15 | D21: =Analysis_Data!L15 | E21: =Analysis_Data!M15 | F21: =Analysis_Data!N15 | G21: =Analysis_Data!O15 | I21: =Analysis_Data!A15 | J21: =Analysis_Data!B15 | K21: =Analysis_Data!C15 | L21: =Analysis_Data!D15 | M21: =Analysis_Data!E15 | N21: =Analysis_Data!F15 | O21: =Analysis_Data!G15
A22: =Analysis_Data!I16 | B22: =Analysis_Data!J16 | C22: =Analysis_Data!K16 | D22: =Analysis_Data!L16 | E22: =Analysis_Data!M16 | F22: =Analysis_Data!N16 | G22: =Analysis_Data!O16 | I22: 합계 | J22: =Analysis_Data!B16 | K22: =Analysis_Data!C16 | L22: =Analysis_Data!D16 | M22: =Analysis_Data!E16 | N22: =Analysis_Data!F16 | O22: =Analysis_Data!G16
A23: 합계 | B23: =Analysis_Data!J17 | C23: =Analysis_Data!K17 | D23: =Analysis_Data!L17 | E23: =Analysis_Data!M17 | F23: =Analysis_Data!N17 | G23: =Analysis_Data!O17

Sheet Analysis_Data
A1: 발행연도 | B1: 도서 수 | C1: 평균 정가 | D1: 평균 판매가 | E1: 평균 할인율 | F1: 판매지수 합계 | G1: 리뷰 수 합계 | I1: 출판사 | J1: 도서 수 | K1: 평균 정가 | L1: 평균 판매가 | M1: 평균 할인율 | N1: 판매지수 합계 | O1: 리뷰 수 합계
A2: 2012 | B2: =COUNTIF(Raw_Data!$I$2:$I$1201, A2) | C2: =AVERAGEIF(Raw_Data!$I$2:$I$1201, A2, Raw_Data!$E$2:$E$1201) | D2: =AVERAGEIF(Raw_Data!$I$2:$I$1201, A2, Raw_Data!$F$2:$F$1201) | E2: =AVERAGEIF(Raw_Data!$I$2:$I$1201, A2, Raw_Data!$K$2:$K$1201) | F2: =SUMIF(Raw_Data!$I$2:$I$1201, A2, Raw_Data!$H$2:$H$1201) | G2: =SUMIF(Raw_Data!$I$2:$I$1201, A2, Raw_Data!$G$2:$G$1201) | I2: 커뮤니케이션북스 | J2: =COUNTIF(Raw_Data!$C$2:$C$1201, I2) | K2: =AVERAGEIF(Raw_Data!$C$2:$C$1201, I2, Raw_Data!$E$2:$E$1201) | L2: =AVERAGEIF(Raw_Data!$C$2:$C$1201, I2, Raw_Data!$F$2:$F$1201) | M2: =AVERAGEIF(Raw_Data!$C$2:$C$1201, I2, Raw_Data!$K$2:$K$1201) | N2: =SUMIF(Raw_Data!$C$2:$C$1201, I2, Raw_Data!$H$2:$H$1201) | O2: =SUMIF(Raw_Data!$C$2:$C$1201, I2, Raw_Data!$G$2:$G$1201)
A3: 2013 | B3: =COUNTIF(Raw_Data!$I$2:$I$1201, A3) | C3: =AVERAGEIF(Raw_Data!$I$2:$I$1201, A3, Raw_Data!$E$2:$E$1201) | D3: =AVERAGEIF(Raw_Data!$I$2:$I$1201, A3, Raw_Data!$F$2:$F$1201) | E3: =AVERAGEIF(Raw_Data!$I$2:$I$1201, A3, Raw_Data!$K$2:$K$1201) | F3: =SUMIF(Raw_Data!$I$2:$I$1201, A3, Raw_Data!$H$2:$H$1201) | G3: =SUMIF(Raw_Data!$I$2:$I$1201, A3, Raw_Data!$G$2:$G$1201) | I3: 한빛미디어 | J3: =COUNTIF(Raw_Data!$C$2:$C$1201, I3) | K3: =AVERAGEIF(Raw_Data!$C$2:$C$1201, I3, Raw_Data!$E$2:$E$1201) | L3: =AVERAGEIF(Raw_Data!$C$2:$C$1201, I3, Raw_Data!$F$2:$F$1201) | M3: =AVERAGEIF(Raw_Data!$C$2:$C$1201, I3, Raw_Data!$K$2:$K$1201) | N3: =SUMIF(Raw_Data!$C$2:$C$1201, I3, Raw_Data!$H$2:$H$1201) | O3: =SUMIF(Raw_Data!$C$2:$C$1201, I3, Raw_Data!$G$2:$G$1201)
A4: 2014 | B4: =COUNTIF(Raw_Data!$I$2:$I$1201, A4) | C4: =AVERAGEIF(Raw_Data!$I$2:$I$1201, A4, Raw_Data!$E$2:$E$1201) | D4: =AVERAGEIF(Raw_Data!$I$2:$I$1201, A4, Raw_Data!$F$2:$F$1201) | E4: =AVERAGEIF(Raw_Data!$I$2:$I$1201, A4, Raw_Data!$K$2:$K$1201) | F4: =SUMIF(Raw_Data!$I$2:$I$1201, A4, Raw_Data!$H$2:$H$1201) | G4: =SUMIF(Raw_Data!$I$2:$I$1201, A4, Raw_Data!$G$2:$G$1201) | I4: 길벗 | J4: =COUNTIF(Raw_Data!$C$2:$C$1201, I4) | K4: =AVERAGEIF(Raw_Data!$C$2:$C$1201, I4, Raw_Data!$E$2:$E$1201) | L4: =AVERAGEIF(Raw_Data!$C$2:$C$1201, I4, Raw_Data!$F$2:$F$1201) | M4: =AVERAGEIF(Raw_Data!$C$2:$C$1201, I4, Raw_Data!$K$2:$K$1201) | N4: =SUMIF(Raw_Data!$C$2:$C$1201, I4, Raw_Data!$H$2:$H$1201) | O4: =SUMIF(Raw_Data!$C$2:$C$1201, I4, Raw_Data!$G$2:$G$1201)
A5: 2015 | B5: =COUNTIF(Raw_Data!$I$2:$I$1201, A5) | C5: =AVERAGEIF(Raw_Data!$I$2:$I$1201, A5, Raw_Data!$E$2:$E$1201) | D5: =AVERAGEIF(Raw_Data!$I$2:$I$1201, A5, Raw_Data!$F$2:$F$1201) | E5: =AVERAGEIF(Raw_Data!$I$2:$I$1201, A5, Raw_Data!$K$2:$K$1201) | F5: =SUMIF(Raw_Data!$I$2:$I$1201, A5, Raw_Data!$H$2:$H$1201) | G5: =SUMIF(Raw_Data!$I$2:$I$1201, A5, Raw_Data!$G$2:$G$1201) | I5: 제이펍 | J5: =COUNTIF(Raw_Data!$C$2:$C$1201, I5) | K5: =AVERAGEIF(Raw_Data!$C$2:$C$1201, I5, Raw_Data!$E$2:$E$1201) | L5: =AVERAGEIF(Raw_Data!$C$2:$C$1201, I5, Raw_Data!$F$2:$F$1201) | M5: =AVERAGEIF(Raw_Data!$C$2:$C$1201, I5, Raw_Data!$K$2:$K$1201) | N5: =SUMIF(Raw_Data!$C$2:$C$1201, I5, Raw_Data!$H$2:$H$1201) | O5: =SUMIF(Raw_Data!$C$2:$C$1201, I5, Raw_Data!$G$2:$G$1201)
A6: 2017 | B6: =COUNTIF(Raw_Data!$I$2:$I$1201, A6) | C6: =AVERAGEIF(Raw_Data!$I$2:$I$1201, A6, Raw_Data!$E$2:$E$1201) | D6: =AVERAGEIF(Raw_Data!$I$2:$I$1201, A6, Raw_Data!$F$2:$F$1201) | E6: =AVERAGEIF(Raw_Data!$I$2:$I$1201, A6, Raw_Data!$K$2:$K$1201) | F6: =SUMIF(Raw_Data!$I$2:$I$1201, A6, Raw_Data!$H$2:$H$1201) | G6: =SUMIF(Raw_Data!$I$2:$I$1201, A6, Raw_Data!$G$2:$G$1201) | I6: 골든래빗 | J6: =COUNTIF(Raw_Data!$C$2:$C$1201, I6) | K6: =AVERAGEIF(Raw_Data!$C$2:$C$1201, I6, Raw_Data!$E$2:$E$1201) | L6: =AVERAGEIF(Raw_Data!$C$2:$C$1201, I6, Raw_Data!$F$2:$F$1201) | M6: =AVERAGEIF(Raw_Data!$C$2:$C$1201, I6, Raw_Data!$K$2:$K$1201) | N6: =SUMIF(Raw_Data!$C$2:$C$1201, I6, Raw_Data!$H$2:$H$1201) | O6: =SUMIF(Raw_Data!$C$2:$C$1201, I6, Raw_Data!$G$2:$G$1201)
A7: 2018 | B7: =COUNTIF(Raw_Data!$I$2:$I$1201, A7) | C7: =AVERAGEIF(Raw_Data!$I$2:$I$1201, A7, Raw_Data!$E$2:$E$1201) | D7: =AVERAGEIF(Raw_Data!$I$2:$I$1201, A7, Raw_Data!$F$2:$F$1201) | E7: =AVERAGEIF(Raw_Data!$I$2:$I$1201, A7, Raw_Data!$K$2:$K$1201) | F7: =SUMIF(Raw_Data!$I$2:$I$1201, A7, Raw_Data!$H$2:$H$1201) | G7: =SUMIF(Raw_Data!$I$2:$I$1201, A7, Raw_Data!$G$2:$G$1201) | I7: 앤써북 | J7: =COUNTIF(Raw_Data!$C$2:$C$1201, I7) | K7: =AVERAGEIF(Raw_Data!$C$2:$C$1201, I7, Raw_Data!$E$2:$E$1201) | L7: =AVERAGEIF(Raw_Data!$C$2:$C$1201, I7, Raw_Data!$F$2:$F$1201) | M7: =AVERAGEIF(Raw_Data!$C$2:$C$1201, I7, Raw_Data!$K$2:$K$1201) | N7: =SUMIF(Raw_Data!$C$2:$C$1201, I7, Raw_Data!$H$2:$H$1201) | O7: =SUMIF(Raw_Data!$C$2:$C$1201, I7, Raw_Data!$G$2:$G$1201)
A8: 2019 | B8: =COUNTIF(Raw_Data!$I$2:$I$1201, A8) | C8: =AVERAGEIF(Raw_Data!$I$2:$I$1201, A8, Raw_Data!$E$2:$E$1201) | D8: =AVERAGEIF(Raw_Data!$I$2:$I$1201, A8, Raw_Data!$F$2:$F$1201) | E8: =AVERAGEIF(Raw_Data!$I$2:$I$1201, A8, Raw_Data!$K$2:$K$1201) | F8: =SUMIF(Raw_Data!$I$2:$I$1201, A8, Raw_Data!$H$2:$H$1201) | G8: =SUMIF(Raw_Data!$I$2:$I$1201, A8, Raw_Data!$G$2:$G$1201) | I8: 위키북스 | J8: =COUNTIF(Raw_Data!$C$2:$C$1201, I8) | K8: =AVERAGEIF(Raw_Data!$C$2:$C$1201, I8, Raw_Data!$E$2:$E$1201) | L8: =AVERAGEIF(Raw_Data!$C$2:$C$1201, I8, Raw_Data!$F$2:$F$1201) | M8: =AVERAGEIF(Raw_Data!$C$2:$C$1201, I8, Raw_Data!$K$2:$K$1201) | N8: =SUMIF(Raw_Data!$C$2:$C$1201, I8, Raw_Data!$H$2:$H$1201) | O8: =SUMIF(Raw_Data!$C$2:$C$1201, I8, Raw_Data!$G$2:$G$1201)
A9: 2020 | B9: =COUNTIF(Raw_Data!$I$2:$I$1201, A9) | C9: =AVERAGEIF(Raw_Data!$I$2:$I$1201, A9, Raw_Data!$E$2:$E$1201) | D9: =AVERAGEIF(Raw_Data!$I$2:$I$1201, A9, Raw_Data!$F$2:$F$1201) | E9: =AVERAGEIF(Raw_Data!$I$2:$I$1201, A9, Raw_Data!$K$2:$K$1201) | F9: =SUMIF(Raw_Data!$I$2:$I$1201, A9, Raw_Data!$H$2:$H$1201) | G9: =SUMIF(Raw_Data!$I$2:$I$1201, A9, Raw_Data!$G$2:$G$1201) | I9: 에이콘출판사 | J9: =COUNTIF(Raw_Data!$C$2:$C$1201, I9) | K9: =AVERAGEIF(Raw_Data!$C$2:$C$1201, I9, Raw_Data!$E$2:$E$1201) | L9: =AVERAGEIF(Raw_Data!$C$2:$C$1201, I9, Raw_Data!$F$2:$F$1201) | M9: =AVERAGEIF(Raw_Data!$C$2:$C$1201, I9, Raw_Data!$K$2:$K$1201) | N9: =SUMIF(Raw_Data!$C$2:$C$1201, I9, Raw_Data!$H$2:$H$1201) | O9: =SUMIF(Raw_Data!$C$2:$C$1201, I9, Raw_Data!$G$2:$G$1201)
A10: 2021 | B10: =COUNTIF(Raw_Data!$I$2:$I$1201, A10) | C10: =AVERAGEIF(Raw_Data!$I$2:$I$1201, A10, Raw_Data!$E$2:$E$1201) | D10: =AVERAGEIF(Raw_Data!$I$2:$I$1201, A10, Raw_Data!$F$2:$F$1201) | E10: =AVERAGEIF(Raw_Data!$I$2:$I$1201, A10, Raw_Data!$K$2:$K$1201) | F10: =SUMIF(Raw_Data!$I$2:$I$1201, A10, Raw_Data!$H$2:$H$1201) | G10: =SUMIF(Raw_Data!$I$2:$I$1201, A10, Raw_Data!$G$2:$G$1201) | I10: BOOKK(부크크) | J10: =COUNTIF(Raw_Data!$C$2:$C$1201, I10) | K10: =AVERAGEIF(Raw_Data!$C$2:$C$1201, I10, Raw_Data!$E$2:$E$1201) | L10: =AVERAGEIF(Raw_Data!$C$2:$C$1201, I10, Raw_Data!$F$2:$F$1201) | M10: =AVERAGEIF(Raw_Data!$C$2:$C$1201, I10, Raw_Data!$K$2:$K$1201) | N10: =SUMIF(Raw_Data!$C$2:$C$1201, I10, Raw_Data!$H$2:$H$1201) | O10: =SUMIF(Raw_Data!$C$2:$C$1201, I10, Raw_Data!$G$2:$G$1201)
A11: 2022 | B11: =COUNTIF(Raw_Data!$I$2:$I$1201, A11) | C11: =AVERAGEIF(Raw_Data!$I$2:$I$1201, A11, Raw_Data!$E$2:$E$1201) | D11: =AVERAGEIF(Raw_Data!$I$2:$I$1201, A11, Raw_Data!$F$2:$F$1201) | E11: =AVERAGEIF(Raw_Data!$I$2:$I$1201, A11, Raw_Data!$K$2:$K$1201) | F11: =SUMIF(Raw_Data!$I$2:$I$1201, A11, Raw_Data!$H$2:$H$1201) | G11: =SUMIF(Raw_Data!$I$2:$I$1201, A11, Raw_Data!$G$2:$G$1201) | I11: 이지스퍼블리싱 | J11: =COUNTIF(Raw_Data!$C$2:$C$1201, I11) | K11: =AVERAGEIF(Raw_Data!$C$2:$C$1201, I11, Raw_Data!$E$2:$E$1201) | L11: =AVERAGEIF(Raw_Data!$C$2:$C$1201, I11, Raw_Data!$F$2:$F$1201) | M11: =AVERAGEIF(Raw_Data!$C$2:$C$1201, I11, Raw_Data!$K$2:$K$1201) | N11: =SUMIF(Raw_Data!$C$2:$C$1201, I11, Raw_Data!$H$2:$H$1201) | O11: =SUMIF(Raw_Data!$C$2:$C$1201, I11, Raw_Data!$G$2:$G$1201)
A12: 2023 | B12: =COUNTIF(Raw_Data!$I$2:$I$1201, A12) | C12: =AVERAGEIF(Raw_Data!$I$2:$I$1201, A12, Raw_Data!$E$2:$E$1201) | D12: =AVERAGEIF(Raw_Data!$I$2:$I$1201, A12, Raw_Data!$F$2:$F$1201) | E12: =AVERAGEIF(Raw_Data!$I$2:$I$1201, A12, Raw_Data!$K$2:$K$1201) | F12: =SUMIF(Raw_Data!$I$2:$I$1201, A12, Raw_Data!$H$2:$H$1201) | G12: =SUMIF(Raw_Data!$I$2:$I$1201, A12, Raw_Data!$G$2:$G$1201) | I12: 성안당 | J12: =COUNTIF(Raw_Data!$C$2:$C$1201, I12) | K12: =AVERAGEIF(Raw_Data!$C$2:$C$1201, I12, Raw_Data!$E$2:$E$1201) | L12: =AVERAGEIF(Raw_Data!$C$2:$C$1201, I12, Raw_Data!$F$2:$F$1201) | M12: =AVERAGEIF(Raw_Data!$C$2:$C$1201, I12, Raw_Data!$K$2:$K$1201) | N12: =SUMIF(Raw_Data!$C$2:$C$1201, I12, Raw_Data!$H$2:$H$1201) | O12: =SUMIF(Raw_Data!$C$2:$C$1201, I12, Raw_Data!$G$2:$G$1201)
A13: 2024 | B13: =COUNTIF(Raw_Data!$I$2:$I$1201, A13) | C13: =AVERAGEIF(Raw_Data!$I$2:$I$1201, A13, Raw_Data!$E$2:$E$1201) | D13: =AVERAGEIF(Raw_Data!$I$2:$I$1201, A13, Raw_Data!$F$2:$F$1201) | E13: =AVERAGEIF(Raw_Data!$I$2:$I$1201, A13, Raw_Data!$K$2:$K$1201) | F13: =SUMIF(Raw_Data!$I$2:$I$1201, A13, Raw_Data!$H$2:$H$1201) | G13: =SUMIF(Raw_Data!$I$2:$I$1201, A13, Raw_Data!$G$2:$G$1201) | I13: 한빛아카데미 | J13: =COUNTIF(Raw_Data!$C$2:$C$1201, I13) | K13: =AVERAGEIF(Raw_Data!$C$2:$C$1201, I13, Raw_Data!$E$2:$E$1201) | L13: =AVERAGEIF(Raw_Data!$C$2:$C$1201, I13, Raw_Data!$F$2:$F$1201) | M13: =AVERAGEIF(Raw_Data!$C$2:$C$1201, I13, Raw_Data!$K$2:$K$1201) | N13: =SUMIF(Raw_Data!$C$2:$C$1201, I13, Raw_Data!$H$2:$H$1201) | O13: =SUMIF(Raw_Data!$C$2:$C$1201, I13, Raw_Data!$G$2:$G$1201)
... A15: 2026 | B15: =COUNTIF(Raw_Data!$I$2:$I$1201, A15) | C15: =AVERAGEIF(Raw_Data!$I$2:$I$1201, A15, Raw_Data!$E$2:$E$1201) | D15: =AVERAGEIF(Raw_Data!$I$2:$I$1201, A15, Raw_Data!$F$2:$F$1201) | E15: =AVERAGEIF(Raw_Data!$I$2:$I$1201, A15, Raw_Data!$K$2:$K$1201) | F15: =SUMIF(Raw_Data!$I$2:$I$1201, A15, Raw_Data!$H$2:$H$1201) | G15: =SUMIF(Raw_Data!$I$2:$I$1201, A15, Raw_Data!$G$2:$G$1201) | I15: 영진닷컴 | J15: =COUNTIF(Raw_Data!$C$2:$C$1201, I15) | K15: =AVERAGEIF(Raw_Data!$C$2:$C$1201, I15, Raw_Data!$E$2:$E$1201) | L15: =AVERAGEIF(Raw_Data!$C$2:$C$1201, I15, Raw_Data!$F$2:$F$1201) | M15: =AVERAGEIF(Raw_Data!$C$2:$C$1201, I15, Raw_Data!$K$2:$K$1201) | N15: =SUMIF(Raw_Data!$C$2:$C$1201, I15, Raw_Data!$H$2:$H$1201) | O15: =SUMIF(Raw_Data!$C$2:$C$1201, I15, Raw_Data!$G$2:$G$1201)
A16: 합계 | B16: =SUM(B2:B15) | C16: =AVERAGE(C2:C15) | D16: =AVERAGE(D2:D15) | E16: =AVERAGE(E2:E15) | F16: =SUM(F2:F15) | G16: =SUM(G2:G15) | I16: 리코멘드 | J16: =COUNTIF(Raw_Data!$C$2:$C$1201, I16) | K16: =AVERAGEIF(Raw_Data!$C$2:$C$1201, I16, Raw_Data!$E$2:$E$1201) | L16: =AVERAGEIF(Raw_Data!$C$2:$C$1201, I16, Raw_Data!$F$2:$F$1201) | M16: =AVERAGEIF(Raw_Data!$C$2:$C$1201, I16, Raw_Data!$K$2:$K$1201) | N16: =SUMIF(Raw_Data!$C$2:$C$1201, I16, Raw_Data!$H$2:$H$1201) | O16: =SUMIF(Raw_Data!$C$2:$C$1201, I16, Raw_Data!$G$2:$G$1201)
I17: 합계 | J17: =SUM(J2:J16) | K17: =AVERAGE(K2:K16) | L17: =AVERAGE(L2:L16) | M17: =AVERAGE(M2:M16) | N17: =SUM(N2:N16) | O17: =SUM(O2:O16)

Sheet Raw_Data
A1: 제목 | B1: 저자 | C1: 출판사 | D1: 발행일 | E1: 정가 | F1: 판매가 | G1: 리뷰 수 | H1: 판매지수 | I1: 발행연도 | J1: 발행월 | K1: 할인율
A2: 클로드 코드로 시작하는 실전 에이전틱 코딩 | B2: Goos Kim | C2: 더 타이즈 | D2: 2026년 05월 | E2: 33000 | F2: 29700 | G2: 11 | H2: 24912 | I2: 2026 | J2: 0 | K2: =(E2-F2)/IF(E2>0,E2,1)
A3: 바로바로 클로드 with 코워크, 스킬, 클로드 코드, 디자인 | B3: 차진우 | C3: 골든래빗 | D3: 2026년 05월 | E3: 28000 | F3: 25200 | G3: 1 | H3: 21747 | I3: 2026 | J3: 0 | K3: =(E3-F3)/IF(E3>0,E3,1)
A4: 조코딩의 바이브 코딩 1인 창업 with 클로드 코드, 수파베이스, 스트라이프 | B4: 조동근 | C4: 한빛미디어 | D4: 2026년 05월 | E4: 30000 | F4: 27000 | G4: 2 | H4: 15939 | I4: 2026 | J4: 0 | K4: =(E4-F4)/IF(E4>0,E4,1)
A5: 하네스 엔지니어링 with 클로드 코드 | B5: 황민호 | C5: 한빛미디어 | D5: 2026년 06월 | E5: 30000 | F5: 27000 | G5: 1 | H5: 10287 | I5: 2026 | J5: 0 | K5: =(E5-F5)/IF(E5>0,E5,1)
A6: 요즘 교사를 위한 에듀테크 5대장 : 캔바, 패들렛, 북크리에이터, 노션, 챗GPT∙제미나이 | B6: 안익재, 황의태 | C6: 앤써북 | D6: 2025년 12월 | E6: 19800 | F6: 17820 | G6: 92 | H6: 36312 | I6: 2025 | J6: 1 | K6: =(E6-F6)/IF(E6>0,E6,1)
A7: AI 시대의 질문력, 프롬프트 엔지니어링 | B7: 류한석 | C7: 코리아닷컴(Korea.com) | D7: 2025년 08월 | E7: 27000 | F7: 24300 | G7: 61 | H7: 68079 | I7: 2025 | J7: 0 | K7: =(E7-F7)/IF(E7>0,E7,1)
A8: 클로드 코드 마스터 | B8: 이남희, 백승현 | C8: 한빛미디어 | D8: 2026년 04월 | E8: 36000 | F8: 32400 | G8: 23 | H8: 17244 | I8: 2026 | J8: 0 | K8: =(E8-F8)/IF(E8>0,E8,1)
A9: 된다! 캡컷 영상 편집 | B9: 지민이 | C9: 이지스퍼블리싱 | D9: 2026년 05월 | E9: 22000 | F9: 19800 | G9: 17 | H9: 10254 | I9: 2026 | J9: 0 | K9: =(E9-F9)/IF(E9>0,E9,1)
A10: 바쁜 교사를 위한 바로 쓰는 AI | B10: 전소영, 이태화, 조두연 | C10: 사회평론아카데미 | D10: 2026년 04월 | E10: 24000 | F10: 21600 | G10: 17 | H10: 17976 | I10: 2026 | J10: 0 | K10: =(E10-F10)/IF(E10>0,E10,1)
A11: 바로바로 제미나이 X 구글 AI | B11: 공냥이 | C11: 골든래빗 | D11: 2026년 06월 | E11: 24000 | F11: 21600 | G11: 1 | H11: 7152 | I11: 2026 | J11: 0 | K11: =(E11-F11)/IF(E11>0,E11,1)
A12: 클로드 코워크 with 스킬, 플러그인 | B12: 클리커, 강민혁 | C12: 한빛미디어 | D12: 2026년 03월 | E12: 26000 | F12: 23400 | G12: 23 | H12: 14913 | I12: 2026 | J12: 0 | K12: =(E12-F12)/IF(E12>0,E12,1)
A13: AI 실전 마스터 칼릭스의 프롬프트 디테일 | B13: 칼릭스(손윤석) | C13: 한빛비즈 | D13: 2026년 04월 | E13: 22000 | F13: 19800 | G13: 12 | H13: 9570 | I13: 2026 | J13: 0 | K13: =(E13-F13)/IF(E13>0,E13,1)
... A249: 다중 에이전트 시스템을 위한 컨텍스트 엔지니어링 | B249: 데니스 로스먼, 류광, 307번역랩 | C249: 위키아카데미 | D249: 2026년 06월 | E249: 32000 | F249: 28800 | G249: 0 | H249: 120 | I249: 2026 | J249: 0 | K249: =(E249-F249)/IF(E249>0,E249,1)
A250: AI 숏폼 동영상 구글 플로우 FLOW 비오3 VEO3 유튜브 쇼츠 인스타그램 릴스 틱톡 네이버 클립 인공지능 만들기 제작 책 학원강의 교재보다 좋은 USB 강좌 초보 교육 사용법 | C250: 액션미디어 | D250: 2026년 06월 | E250: 39800 | F250: 39800 | G250: 0 | H250: 120 | I250: 2026 | J250: 0 | K250: =(E250-F250)/IF(E250>0,E250,1)
A251: AI 탐구 수업 | B251: 정종수 | C251: 플루토 | D251: 2026년 05월 | E251: 17000 | F251: 15300 | G251: 3 | H251: 489 | I251: 2026 | J251: 0 | K251: =(E251-F251)/IF(E251>0,E251,1)
A252: IT 트렌드 2026 | B252: 김지현 | C252: 크레타 | D252: 2025년 10월 | E252: 20000 | F252: 18000 | G252: 23 | H252: 2787 | I252: 2025 | J252: 1 | K252: =(E252-F252)/IF(E252>0,E252,1)
A253: 그림으로 이해하는 챗GPT 구조와 기술 | B253: 나카타니 슈요, 박광수 | C253: 길벗 | D253: 2025년 11월 | E253: 24000 | F253: 21600 | G253: 19 | H253: 1524 | I253: 2025 | J253: 1 | K253: =(E253-F253)/IF(E253>0,E253,1)
A254: 생성형 AI 활용 백과사전 | B254: 다쿠치 카즈히로, 모리시마 료코, 이시타니 마사키, 서수환 | C254: 길벗 | D254: 2025년 06월 | E254: 24000 | F254: 21600 | G254: 49 | H254: 5124 | I254: 2025 | J254: 0 | K254: =(E254-F254)/IF(E254>0,E254,1)
A255: AI를 활용한 법률문서 작성법 | B255: 김종엽 | C255: (주)박영사 | D255: 2025년 05월 | E255: 27000 | F255: 27000 | G255: 6 | H255: 2304 | I255: 2025 | J255: 0 | K255: =(E255-F255)/IF(E255>0,E255,1)
A256: 한 걸음 앞선 일잘러가 지금 꼭 알아야 할 바이브 코딩 with 커서 | B256: 김태헌 | C256: 길벗 | D256: 2026년 02월 | E256: 30000 | F256: 27000 | G256: 14 | H256: 1326 | I256: 2026 | J256: 0 | K256: =(E256-F256)/IF(E256>0,E256,1)
A257: 정말 쉽네? 챗GPT 입문 | B257: 오힘찬 | C257: 골든래빗 | D257: 2024년 10월 | E257: 22000 | F257: 19800 | G257: 149 | H257: 2418 | I257: 2024 | J257: 1 | K257: =(E257-F257)/IF(E257>0,E257,1)
A258: AX 100배의 법칙 | B258: 황재선 | C258: 좋은습관연구소 | D258: 2025년 06월 | E258: 25000 | F258: 22500 | G258: 4 | H258: 3252 | I258: 2025 | J258: 0 | K258: =(E258-F258)/IF(E258>0,E258,1)
A259: AI로 일하는 기술 | B259: 장동인 | C259: 한빛미디어 | D259: 2022년 01월 | E259: 18000 | F259: 16200 | G259: 32 | H259: 1032 | I259: 2022 | J259: 0 | K259: =(E259-F259)/IF(E259>0,E259,1)
A260: LLM 엔지니어링 | B260: 폴 이우수틴, 막심 라본, 조우철 | C260: 한빛미디어 | D260: 2025년 05월 | E260: 38000 | F260: 34200 | G260: 18 | H260: 1998 | I260: 2025 | J260: 0 | K260: =(E260-F260)/IF(E260>0,E260,1)
A261: 올라마와 오픈소스 LLM을 활용한 AI 에이전트 개발 입문 | B261: 서영배, 김병규, 임재봉 | C261: 위키북스 | D261: 2026년 01월 | E261: 28000 | F261: 25200 | G261: 2 | H261: 2109 | I261: 2026 | J261: 0 | K261: =(E261-F261)/IF(E261>0,E261,1)
A262: 벡터 데이터베이스 설계와 구축 | B262: 송한림 | C262: 아이리포 | D262: 2025년 03월 | E262: 17800 | F262: 16020 | G262: 7 | H262: 3150 | I262: 2025 | J262: 0 | K262: =(E262-F262)/IF(E262>0,E262,1)
... A553: 한 번에 완성하는 AI 영상 제작 with 챗GPT+소라+브루 | B553: 권유라 | C553: 제이펍 | D553: 2025년 06월 | E553: 20000 | F553: 18000 | G553: 22 | H553: 3540 | I553: 2025 | J553: 0 | K553: =(E553-F553)/IF(E553>0,E553,1)
A554: Data AI | C554: 호산나 | D554: 2026년 05월 | E554: 35000 | F554: 33250 | G554: 6 | H554: 168 | I554: 2026 | J554: 0 | K554: =(E554-F554)/IF(E554>0,E554,1)
A555: AI 시대 사고의 정석 - 유추 | B555: 이진화 | C555: 지식과감성# | D555: 2026년 05월 | E555: 23000 | F555: 20700 | G555: 1 | H555: 168 | I555: 2026 | J555: 0 | K555: =(E555-F555)/IF(E555>0,E555,1)
A556: AI를 직원처럼 쓰는 마케팅 자동화 시스템 | B556: 이종구, 이정화, 김회균, 손정화 | C556: 디지털콘텐츠그룹 | D556: 2026년 05월 | E556: 24000 | F556: 21600 | G556: 0 | H556: 168 | I556: 2026 | J556: 0 | K556: =(E556-F556)/IF(E556>0,E556,1)
A557: AI 시대의 행정자동결정 | B557: 정남철 | C557: 커뮤니케이션북스 | D557: 2026년 05월 | E557: 12000 | F557: 12000 | G557: 0 | H557: 138 | I557: 2026 | J557: 0 | K557: =(E557-F557)/IF(E557>0,E557,1)
A558: 말로 만드는 창업의 시대 | B558: 심재우, 선웅규 | C558: 진한엠앤비 | D558: 2026년 05월 | E558: 23000 | F558: 21850 | G558: 0 | H558: 192 | I558: 2026 | J558: 0 | K558: =(E558-F558)/IF(E558>0,E558,1)
A559: AI로 쉽게 자기역사 쓰기 | B559: 진순희 | C559: 씽크스마트 | D559: 2026년 03월 | E559: 17000 | F559: 15300 | G559: 19 | H559: 186 | I559: 2026 | J559: 0 | K559: =(E559-F559)/IF(E559>0,E559,1)
A560: 수학으로 이해하는 기초강화학습 | B560: 이동환 | C560: 가우스출판 | D560: 2025년 03월 | E560: 35000 | F560: 31500 | G560: 0 | H560: 198 | I560: 2025 | J560: 0 | K560: =(E560-F560)/IF(E560>0,E560,1)
A561: 핵심 딥러닝 입문: RNN, LSTM, GRU, VAE, GAN 구현 | B561: 아즈마 유키나가, 최재원, 장건희 | C561: 책만 | D561: 2020년 12월 | E561: 28000 | F561: 25200 | G561: 4 | H561: 198 | I561: 2020 | J561: 1 | K561: =(E561-F561)/IF(E561>0,E561,1)
A562: 인공지능과 국제정치 전환 | B562: 김상배, 이원태, 유인태, 이승주, 윤정현, 정보 더 보기/감추기, 김상배, 이원태, 유인태, 이승주, 윤정현, 이종진, 정헌주, 윤대엽, 이수연, 송태은 | C562: 한울아카데미 | D562: 2025년 10월 | E562: 39000 | F562: 39000 | G562: 0 | H562: 204 | I562: 2025 | J562: 1 | K562: =(E562-F562)/IF(E562>0,E562,1)
A563: AI 코드, 디코딩: AI 시대, 개발자의 연봉과 가치를 증명하는 코드 리터러시 | B563: 엄경률 | C563: BOOKK(부크크) | D563: 2025년 07월 | E563: 28900 | F563: 28900 | G563: 0 | H563: 192 | I563: 2025 | J563: 0 | K563: =(E563-F563)/IF(E563>0,E563,1)
A564: AI 에이전트와 인간 설득의 종말 | B564: 유경아 | C564: 커뮤니케이션북스 | D564: 2026년 04월 | E564: 12000 | F564: 12000 | G564: 2 | H564: 186 | I564: 2026 | J564: 0 | K564: =(E564-F564)/IF(E564>0,E564,1)
A565: 리액트 인터뷰 가이드 | B565: 수디르 조나, 앤드류 바이스덴, 김용찬, 강주희 | C565: 위키북스 | D565: 2024년 08월 | E565: 28000 | F565: 25200 | G565: 5 | H565: 150 | I565: 2024 | J565: 0 | K565: =(E565-F565)/IF(E565>0,E565,1)
...

Sheet 커뮤니케이션북스
A1: 제목 | B1: 저자 | C1: 출판사 | D1: 발행일 | E1: 정가 | F1: 판매가 | G1: 리뷰 수 | H1: 판매지수 | I1: 발행연도 | J1: 발행월 | K1: 할인율
A2: 생성형 AI 시대 수학 교육 | B2: 유주연, 정민주 | C2: 커뮤니케이션북스 | D2: 2026년 03월 | E2: 12000 | F2: 12000 | G2: 0 | H2: 246 | I2: 2026 | J2: 0 | K2: =(E2-F2)/IF(E2>0,E2,1)
A3: AI 수업 설계 | B3: 이다연 | C3: 커뮤니케이션북스 | D3: 2026년 05월 | E3: 12000 | F3: 12000 | G3: 0 | H3: 144 | I3: 2026 | J3: 0 | K3: =(E3-F3)/IF(E3>0,E3,1)
A4: AI 로봇 공학의 철학적 뿌리 | B4: 박우석 | C4: 커뮤니케이션북스 | D4: 2025년 11월 | E4: 12000 | F4: 12000 | G4: 0 | H4: 108 | I4: 2025 | J4: 1 | K4: =(E4-F4)/IF(E4>0,E4,1)
A5: 인공지능과 의식 | B5: 한정규 | C5: 커뮤니케이션북스 | D5: 2025년 05월 | E5: 12000 | F5: 12000 | G5: 1 | H5: 108 | I5: 2025 | J5: 0 | K5: =(E5-F5)/IF(E5>0,E5,1)
A6: 생성형 AI와 워터마크 | B6: 소병수 | C6: 커뮤니케이션북스 | D6: 2025년 03월 | E6: 12000 | F6: 12000 | G6: 1 | H6: 72 | I6: 2025 | J6: 0 | K6: =(E6-F6)/IF(E6>0,E6,1)
A7: 생성형 AI와 사변적 디자인 | B7: 장순규 | C7: 커뮤니케이션북스 | D7: 2026년 04월 | E7: 12000 | F7: 12000 | G7: 0 | H7: 90 | I7: 2026 | J7: 0 | K7: =(E7-F7)/IF(E7>0,E7,1)
A8: AI와 다도 교육 | B8: 경혜영, 윤병화 | C8: 커뮤니케이션북스 | D8: 2025년 12월 | E8: 12000 | F8: 12000 | G8: 0 | H8: 72 | I8: 2025 | J8: 1 | K8: =(E8-F8)/IF(E8>0,E8,1)
A9: AI와 신용 평가 | B9: 최성민 | C9: 커뮤니케이션북스 | D9: 2024년 11월 | E9: 12000 | F9: 12000 | G9: 5 | H9: 72 | I9: 2024 | J9: 1 | K9: =(E9-F9)/IF(E9>0,E9,1)
A10: AI 프롬프트와 토픽 모델링 | B10: 정동균, 이종화 | C10: 커뮤니케이션북스 | D10: 2026년 05월 | E10: 12000 | F10: 12000 | G10: 0 | H10: 270 | I10: 2026 | J10: 0 | K10: =(E10-F10)/IF(E10>0,E10,1)
A11: AI 시대의 질적 연구 | B11: 김영순 | C11: 커뮤니케이션북스 | D11: 2026년 03월 | E11: 12000 | F11: 12000 | G11: 0 | H11: 234 | I11: 2026 | J11: 0 | K11: =(E11-F11)/IF(E11>0,E11,1)
A12: 생성형 AI와 스마트 물류 혁신 | B12: 정재엽 | C12: 커뮤니케이션북스 | D12: 2026년 04월 | E12: 12000 | F12: 12000 | G12: 0 | H12: 144 | I12: 2026 | J12: 0 | K12: =(E12-F12)/IF(E12>0,E12,1)
A13: 저전력 AI 반도체 | B13: 최종수 | C13: 커뮤니케이션북스 | D13: 2025년 03월 | E13: 12000 | F13: 12000 | G13: 0 | H13: 216 | I13: 2025 | J13: 0 | K13: =(E13-F13)/IF(E13>0,E13,1)
... A180: 비즈니스 모델과 AI | B180: 이경전 | C180: 커뮤니케이션북스 | D180: 2025년 01월 | E180: 12000 | F180: 12000 | G180: 0 | H180: 270 | I180: 2025 | J180: 0 | K180: =(E180-F180)/IF(E180>0,E180,1)
A181: 합계 및 평균 요약 | E181: =AVERAGE(E2:E180) | F181: =AVERAGE(F2:F180) | G181: =SUM(G2:G180) | H181: =SUM(H2:H180) | K181: =AVERAGE(K2:K180)

Sheet 한빛미디어
A1: 제목 | B1: 저자 | C1: 출판사 | D1: 발행일 | E1: 정가 | F1: 판매가 | G1: 리뷰 수 | H1: 판매지수 | I1: 발행연도 | J1: 발행월 | K1: 할인율
A2: 조코딩의 바이브 코딩 1인 창업 with 클로드 코드, 수파베이스, 스트라이프 | B2: 조동근 | C2: 한빛미디어 | D2: 2026년 05월 | E2: 30000 | F2: 27000 | G2: 2 | H2: 15939 | I2: 2026 | J2: 0 | K2: =(E2-F2)/IF(E2>0,E2,1)
A3: 하네스 엔지니어링 with 클로드 코드 | B3: 황민호 | C3: 한빛미디어 | D3: 2026년 06월 | E3: 30000 | F3: 27000 | G3: 1 | H3: 10287 | I3: 2026 | J3: 0 | K3: =(E3-F3)/IF(E3>0,E3,1)
A4: 클로드 코드 마스터 | B4: 이남희, 백승현 | C4: 한빛미디어 | D4: 2026년 04월 | E4: 36000 | F4: 32400 | G4: 23 | H4: 17244 | I4: 2026 | J4: 0 | K4: =(E4-F4)/IF(E4>0,E4,1)
A5: 클로드 코워크 with 스킬, 플러그인 | B5: 클리커, 강민혁 | C5: 한빛미디어 | D5: 2026년 03월 | E5: 26000 | F5: 23400 | G5: 23 | H5: 14913 | I5: 2026 | J5: 0 | K5: =(E5-F5)/IF(E5>0,E5,1)
A6: 요즘 교사를 위한 AI 수업 활용 가이드 with 2022 개정 교육과정 | B6: 박진환, 공지훈, 서원진 | C6: 한빛미디어 | D6: 2025년 05월 | E6: 20000 | F6: 18000 | G6: 65 | H6: 87927 | I6: 2025 | J6: 0 | K6: =(E6-F6)/IF(E6>0,E6,1)
A7: 요즘 교사를 위한 에듀테크 수업 활용 가이드 with 2022 개정 교육과정 | B7: 박진환, 서원진, 박권 | C7: 한빛미디어 | D7: 2026년 04월 | E7: 24000 | F7: 21600 | G7: 123 | H7: 11856 | I7: 2026 | J7: 0 | K7: =(E7-F7)/IF(E7>0,E7,1)
A8: 바이브 코더를 위한 최소한의 AI/IT 지식 | B8: 클리커, 이희영 | C8: 한빛미디어 | D8: 2026년 04월 | E8: 22000 | F8: 19800 | G8: 52 | H8: 7251 | I8: 2026 | J8: 0 | K8: =(E8-F8)/IF(E8>0,E8,1)
A9: 오픈클로 with GPT, 제미나이, 클로드 | B9: 강민혁 | C9: 한빛미디어 | D9: 2026년 03월 | E9: 22000 | F9: 19800 | G9: 25 | H9: 12063 | I9: 2026 | J9: 0 | K9: =(E9-F9)/IF(E9>0,E9,1)
A10: AI 에이전트 엔지니어링 | B10: 마이클 알바다, 강민혁 | C10: 한빛미디어 | D10: 2026년 01월 | E10: 32000 | F10: 28800 | G10: 17 | H10: 12336 | I10: 2026 | J10: 0 | K10: =(E10-F10)/IF(E10>0,E10,1)
A11: 요즘 교사를 위한 AI 바이브 코딩 활용 가이드 with 2022 개정 교육과정 | B11: 공지훈, 곽수창, 박준효 | C11: 한빛미디어 | D11: 2026년 05월 | E11: 22000 | F11: 19800 | G11: 97 | H11: 5553 | I11: 2026 | J11: 0 | K11: =(E11-F11)/IF(E11>0,E11,1)
A12: 만들면서 배우는 AI 에이전트 개발 입문+실전 | B12: 박나연(공원나연) | C12: 한빛미디어 | D12: 2026년 05월 | E12: 37000 | F12: 33300 | G12: 42 | H12: 4923 | I12: 2026 | J12: 0 | K12: =(E12-F12)/IF(E12>0,E12,1)
A13: 누구나 아는 나만 모르는 제미나이 | B13: 이성원 | C13: 한빛미디어 | D13: 2026년 01월 | E13: 19000 | F13: 17100 | G13: 43 | H13: 14067 | I13: 2026 | J13: 0 | K13: =(E13-F13)/IF(E13>0,E13,1)
... A113: 챗GPT 제대로 써먹기 | B113: 조민정 | C113: 한빛미디어 | D113: 2024년 09월 | E113: 22000 | F113: 19800 | G113: 26 | H113: 288 | I113: 2024 | J113: 0 | K113: =(E113-F113)/IF(E113>0,E113,1)
A114: 합계 및 평균 요약 | E114: =AVERAGE(E2:E113) | F114: =AVERAGE(F2:F113) | G114: =SUM(G2:G113) | H114: =SUM(H2:H113) | K114: =AVERAGE(K2:K113)

Sheet 길벗
A1: 제목 | B1: 저자 | C1: 출판사 | D1: 발행일 | E1: 정가 | F1: 판매가 | G1: 리뷰 수 | H1: 판매지수 | I1: 발행연도 | J1: 발행월 | K1: 할인율
A2: AI 자율학습 제미나이로 일 잘하는 법 | B2: 성구(강성규) | C2: 길벗 | D2: 2026년 04월 | E2: 26000 | F2: 23400 | G2: 44 | H2: 3900 | I2: 2026 | J2: 0 | K2: =(E2-F2)/IF(E2>0,E2,1)
A3: AI 자율학습 클로드 코드·코덱스 CLI·제미나이 CLI 완전 활용법 | B3: Dave Lee | C3: 길벗 | D3: 2026년 02월 | E3: 32000 | F3: 28800 | G3: 25 | H3: 6822 | I3: 2026 | J3: 0 | K3: =(E3-F3)/IF(E3>0,E3,1)
A4: AI가 다 하고 내가 돈 버는 앱 만들기 | B4: 서희찬 | C4: 길벗 | D4: 2026년 05월 | E4: 28000 | F4: 25200 | G4: 5 | H4: 1194 | I4: 2026 | J4: 0 | K4: =(E4-F4)/IF(E4>0,E4,1)
A5: 캔바로 만든 디자인, 돈이 됩니다 | B5: 리몬(안형선) | C5: 길벗 | D5: 2026년 06월 | E5: 22000 | F5: 19800 | G5: 7 | H5: 1530 | I5: 2026 | J5: 0 | K5: =(E5-F5)/IF(E5>0,E5,1)
A6: 그림으로 이해하는 AWS 구조와 기술 | B6: 오가사와라 시게타카, 박광수 | C6: 길벗 | D6: 2026년 04월 | E6: 26000 | F6: 23400 | G6: 44 | H6: 1455 | I6: 2026 | J6: 0 | K6: =(E6-F6)/IF(E6>0,E6,1)
A7: 밑바닥부터 만들면서 배우는 LLM | B7: 세바스찬 라시카, 박해선 | C7: 길벗 | D7: 2025년 09월 | E7: 40000 | F7: 36000 | G7: 27 | H7: 11604 | I7: 2025 | J7: 0 | K7: =(E7-F7)/IF(E7>0,E7,1)
A8: M365 코파일럿 무작정 따라하기 | B8: 김시연, 서지영 | C8: 길벗 | D8: 2025년 04월 | E8: 22000 | F8: 19800 | G8: 7 | H8: 3468 | I8: 2025 | J8: 0 | K8: =(E8-F8)/IF(E8>0,E8,1)
A9: 한 걸음 앞선 개발자가 지금 꼭 알아야 할 클로드 코드 | B9: 조훈, 정찬훈 | C9: 길벗 | D9: 2025년 09월 | E9: 26000 | F9: 23400 | G9: 19 | H9: 9822 | I9: 2025 | J9: 0 | K9: =(E9-F9)/IF(E9>0,E9,1)
A10: 모두의 딥러닝 | B10: 조태호 | C10: 길벗 | D10: 2025년 04월 | E10: 29000 | F10: 26100 | G10: 13 | H10: 3582 | I10: 2025 | J10: 0 | K10: =(E10-F10)/IF(E10>0,E10,1)
A11: 제로클릭 | B11: 손승완 | C11: 길벗 | D11: 2026년 01월 | E11: 18800 | F11: 16920 | G11: 49 | H11: 5016 | I11: 2026 | J11: 0 | K11: =(E11-F11)/IF(E11>0,E11,1)
A12: A2A × MCP 멀티에이전트 오케스트레이션 실전 | B12: 서지영 | C12: 길벗 | D12: 2026년 03월 | E12: 33000 | F12: 29700 | G12: 16 | H12: 1212 | I12: 2026 | J12: 0 | K12: =(E12-F12)/IF(E12>0,E12,1)
A13: AI 영상 제작 | B13: 민지영, 문수민, 전은재, 앤미디어 | C13: 길벗 | D13: 2024년 06월 | E13: 25000 | F13: 22500 | G13: 95 | H13: 6018 | I13: 2024 | J13: 0 | K13: =(E13-F13)/IF(E13>0,E13,1)
... A68: AI 원더랜드 | B68: 안재홍 | C68: 길벗 | D68: 2024년 05월 | E68: 25000 | F68: 22500 | G68: 9 | H68: 264 | I68: 2024 | J68: 0 | K68: =(E68-F68)/IF(E68>0,E68,1)
A69: 합계 및 평균 요약 | E69: =AVERAGE(E2:E68) | F69: =AVERAGE(F2:F68) | G69: =SUM(G2:G68) | H69: =SUM(H2:H68) | K69: =AVERAGE(K2:K68)

Sheet 제이펍
A1: 제목 | B1: 저자 | C1: 출판사 | D1: 발행일 | E1: 정가 | F1: 판매가 | G1: 리뷰 수 | H1: 판매지수 | I1: 발행연도 | J1: 발행월 | K1: 할인율
A2: 수업에 바로 쓰는 일잘러 선생님의 캔바 Canva 활용법 | B2: 황은지 | C2: 제이펍 | D2: 2026년 05월 | E2: 22000 | F2: 19800 | G2: 32 | H2: 6069 | I2: 2026 | J2: 0 | K2: =(E2-F2)/IF(E2>0,E2,1)
A3: LLM을 위한 프롬프트 엔지니어링 | B3: 존 베리먼, 앨버트 지글러, 김정인 | C3: 제이펍 | D3: 2026년 01월 | E3: 28000 | F3: 25200 | G3: 7 | H3: 2784 | I3: 2026 | J3: 0 | K3: =(E3-F3)/IF(E3>0,E3,1)
A4: 처음 만나는 AI 에이전트 with 랭체인 & MCP | B4: 김재엽, 이민준 | C4: 제이펍 | D4: 2026년 05월 | E4: 30000 | F4: 27000 | G4: 0 | H4: 1758 | I4: 2026 | J4: 0 | K4: =(E4-F4)/IF(E4>0,E4,1)
A5: 30가지 예제로 따라 하며 배우는 ComfyUI 클라우드 | B5: 여승호, 신무경 | C5: 제이펍 | D5: 2026년 03월 | E5: 22000 | F5: 19800 | G5: 9 | H5: 1410 | I5: 2026 | J5: 0 | K5: =(E5-F5)/IF(E5>0,E5,1)
A6: AI가 일하는 법 | B6: 로널드 크노이젤, 한선용 | C6: 제이펍 | D6: 2026년 05월 | E6: 22800 | F6: 20520 | G6: 5 | H6: 474 | I6: 2026 | J6: 0 | K6: =(E6-F6)/IF(E6>0,E6,1)
A7: 수노로 시작하는 AI 작곡 | B7: 강성우, 한나래 | C7: 제이펍 | D7: 2025년 12월 | E7: 20000 | F7: 18000 | G7: 21 | H7: 4074 | I7: 2025 | J7: 1 | K7: =(E7-F7)/IF(E7>0,E7,1)
A8: LUVIT♥ 클로드와 함께하는 LLM 프로젝트 | B8: 이승우 | C8: 제이펍 | D8: 2026년 04월 | E8: 38000 | F8: 34200 | G8: 2 | H8: 1026 | I8: 2026 | J8: 0 | K8: =(E8-F8)/IF(E8>0,E8,1)
A9: 누구나 쉽게 시작하는 방구석 1인 앱 창업 | B9: 김건희 | C9: 제이펍 | D9: 2026년 03월 | E9: 28000 | F9: 25200 | G9: 5 | H9: 1818 | I9: 2026 | J9: 0 | K9: =(E9-F9)/IF(E9>0,E9,1)
A10: 진짜 쓰는 프리미어 영상 편집 2026 (최신개정판) | B10: 조블리 | C10: 제이펍 | D10: 2026년 06월 | E10: 26000 | F10: 23400 | G10: 0 | H10: 180 | I10: 2026 | J10: 0 | K10: =(E10-F10)/IF(E10>0,E10,1)
A11: 대체불가능 | B11: 파스칼 보넷, 김정민 | C11: 제이펍 | D11: 2026년 02월 | E11: 22000 | F11: 19800 | G11: 11 | H11: 864 | I11: 2026 | J11: 0 | K11: =(E11-F11)/IF(E11>0,E11,1)
A12: 챗GPT와 엑셀로 만드는 주식 & 암호화폐 자동매매 시스템 | B12: 설근민 | C12: 제이펍 | D12: 2025년 08월 | E12: 25000 | F12: 22500 | G12: 8 | H12: 2574 | I12: 2025 | J12: 0 | K12: =(E12-F12)/IF(E12>0,E12,1)
A13: 에지 컴퓨팅과 피지컬 AI를 위한 라즈베리파이 5 | B13: 허경용 | C13: 제이펍 | D13: 2026년 02월 | E13: 30000 | F13: 27000 | G13: 0 | H13: 708 | I13: 2026 | J13: 0 | K13: =(E13-F13)/IF(E13>0,E13,1)
... A60: 라마인덱스로 배우는 데이터 기반 AI 애플리케이션 | B60: 안드레이 게오르기우, 동동구 | C60: 제이펍 | D60: 2025년 10월 | E60: 32000 | F60: 28800 | G60: 3 | H60: 330 | I60: 2025 | J60: 1 | K60: =(E60-F60)/IF(E60>0,E60,1)
A61: 합계 및 평균 요약 | E61: =AVERAGE(E2:E60) | F61: =AVERAGE(F2:F60) | G61: =SUM(G2:G60) | H61: =SUM(H2:H60) | K61: =AVERAGE(K2:K60)

Sheet 골든래빗
A1: 제목 | B1: 저자 | C1: 출판사 | D1: 발행일 | E1: 정가 | F1: 판매가 | G1: 리뷰 수 | H1: 판매지수 | I1: 발행연도 | J1: 발행월 | K1: 할인율
A2: 바로바로 클로드 with 코워크, 스킬, 클로드 코드, 디자인 | B2: 차진우 | C2: 골든래빗 | D2: 2026년 05월 | E2: 28000 | F2: 25200 | G2: 1 | H2: 21747 | I2: 2026 | J2: 0 | K2: =(E2-F2)/IF(E2>0,E2,1)
A3: 바로바로 제미나이 X 구글 AI | B3: 공냥이 | C3: 골든래빗 | D3: 2026년 06월 | E3: 24000 | F3: 21600 | G3: 1 | H3: 7152 | I3: 2026 | J3: 0 | K3: =(E3-F3)/IF(E3>0,E3,1)
A4: 이게 되네? 캔바 AI 미친 활용법 47제 | B4: 이지쌤(이지훈) | C4: 골든래빗 | D4: 2026년 05월 | E4: 24000 | F4: 21600 | G4: 15 | H4: 4869 | I4: 2026 | J4: 0 | K4: =(E4-F4)/IF(E4>0,E4,1)
A5: 세컨드 브레인은 옵시디언 with 클로드 코드 | B5: 시안 | C5: 골든래빗 | D5: 2026년 04월 | E5: 25000 | F5: 23750 | G5: 36 | H5: 5397 | I5: 2026 | J5: 0 | K5: =(E5-F5)/IF(E5>0,E5,1)
A6: 요즘 바이브 코딩 코덱스 완벽 가이드 | B6: 윤재원 | C6: 골든래빗 | D6: 2026년 02월 | E6: 28000 | F6: 25200 | G6: 35 | H6: 5541 | I6: 2026 | J6: 0 | K6: =(E6-F6)/IF(E6>0,E6,1)
A7: 요즘 바이브 코딩 커서 X 클로드 코드 실전 외주 돈 벌기 | B7: 불혹코딩 | C7: 골든래빗 | D7: 2026년 05월 | E7: 26000 | F7: 23400 | G7: 14 | H7: 4137 | I7: 2026 | J7: 0 | K7: =(E7-F7)/IF(E7>0,E7,1)
A8: 요즘 바이브 코딩 안티그래비티 완벽 가이드 | B8: 최지호 | C8: 골든래빗 | D8: 2026년 02월 | E8: 28000 | F8: 25200 | G8: 29 | H8: 18714 | I8: 2026 | J8: 0 | K8: =(E8-F8)/IF(E8>0,E8,1)
A9: 이게 되네? 나노바나나 2 AI 비포&애프터 미친 활용법 82제 | B9: 쌩초 | C9: 골든래빗 | D9: 2026년 05월 | E9: 24000 | F9: 21600 | G9: 96 | H9: 3228 | I9: 2026 | J9: 0 | K9: =(E9-F9)/IF(E9>0,E9,1)
A10: 바로바로 바이브 코딩 with 커서 AI | B10: 박현규 | C10: 골든래빗 | D10: 2026년 04월 | E10: 30000 | F10: 27000 | G10: 10 | H10: 3687 | I10: 2026 | J10: 0 | K10: =(E10-F10)/IF(E10>0,E10,1)
A11: 요즘 바이브 코딩 클로드 코드 완벽 가이드 | B11: 최지호 | C11: 골든래빗 | D11: 2025년 09월 | E11: 24000 | F11: 21600 | G11: 19 | H11: 28527 | I11: 2025 | J11: 0 | K11: =(E11-F11)/IF(E11>0,E11,1)
A12: 생존을 위한 최소한의 AI 교양 | B12: 조남호 | C12: 골든래빗 | D12: 2026년 06월 | E12: 25000 | F12: 22500 | G12: 22 | H12: 1344 | I12: 2026 | J12: 0 | K12: =(E12-F12)/IF(E12>0,E12,1)
A13: 요즘 바이브 코딩 하네스 with 클로드 코드 | B13: 조성진 | C13: 골든래빗 | D13: 2026년 06월 | E13: 30000 | F13: 27000 | G13: 0 | H13: 1254 | I13: 2026 | J13: 0 | K13: =(E13-F13)/IF(E13>0,E13,1)
... A39: Must Have 머신러닝·딥러닝 문제해결 전략 | B39: 신백균 | C39: 골든래빗 | D39: 2022년 04월 | E39: 38000 | F39: 34200 | G39: 2 | H39: 258 | I39: 2022 | J39: 0 | K39: =(E39-F39)/IF(E39>0,E39,1)
A40: 합계 및 평균 요약 | E40: =AVERAGE(E2:E39) | F40: =AVERAGE(F2:F39) | G40: =SUM(G2:G39) | H40: =SUM(H2:H39) | K40: =AVERAGE(K2:K39)

Sheet 앤써북
A1: 제목 | B1: 저자 | C1: 출판사 | D1: 발행일 | E1: 정가 | F1: 판매가 | G1: 리뷰 수 | H1: 판매지수 | I1: 발행연도 | J1: 발행월 | K1: 할인율
A2: 요즘 교사를 위한 에듀테크 5대장 : 캔바, 패들렛, 북크리에이터, 노션, 챗GPT∙제미나이 | B2: 안익재, 황의태 | C2: 앤써북 | D2: 2025년 12월 | E2: 19800 | F2: 17820 | G2: 92 | H2: 36312 | I2: 2025 | J2: 1 | K2: =(E2-F2)/IF(E2>0,E2,1)
A3: 수업과 업무에 바로 적용하는 생성형 AI 활용 58제 | B3: 임세범 | C3: 앤써북 | D3: 2026년 04월 | E3: 18800 | F3: 16920 | G3: 7 | H3: 4023 | I3: 2026 | J3: 0 | K3: =(E3-F3)/IF(E3>0,E3,1)
A4: 교사를 위한 패들렛 Padlet | B4: 안익재 | C4: 앤써북 | D4: 2025년 03월 | E4: 16800 | F4: 15120 | G4: 47 | H4: 12774 | I4: 2025 | J4: 0 | K4: =(E4-F4)/IF(E4>0,E4,1)
A5: 요즘 예체능 수업을 위한 에듀테크 활용법 223제 | B5: 박래혁 | C5: 앤써북 | D5: 2026년 05월 | E5: 23300 | F5: 20970 | G5: 29 | H5: 1839 | I5: 2026 | J5: 0 | K5: =(E5-F5)/IF(E5>0,E5,1)
A6: 요즘 교사를 위한 구글 AI 3대장_제미나이, 노트북LM, AI 스튜디오 | B6: 송명신, 최연준, 최수진, 양서현 | C6: 앤써북 | D6: 2026년 06월 | E6: 17700 | F6: 15930 | G6: 3 | H6: 360 | I6: 2026 | J6: 0 | K6: =(E6-F6)/IF(E6>0,E6,1)
A7: 2022 개정 교육과정 평가, AI로 날개를 달다 (개념기반 교육과정) | B7: 지미정, 오한나, 노명호, 권의선, 김영수, 정보 더 보기/감추기, 지미정, 오한나, 노명호, 권의선, 김영수, 이진원, 장희영, 소민영, 조보현 | C7: 앤써북 | D7: 2024년 09월 | E7: 21000 | F7: 18900 | G7: 19 | H7: 11121 | I7: 2024 | J7: 0 | K7: =(E7-F7)/IF(E7>0,E7,1)
A8: 요즘 교실 혁신의 공식 AI·에듀테크 활용법 with 2022 개정 교육과정 | B8: 진제헌 | C8: 앤써북 | D8: 2026년 05월 | E8: 23300 | F8: 20970 | G8: 6 | H8: 1710 | I8: 2026 | J8: 0 | K8: =(E8-F8)/IF(E8>0,E8,1)
A9: 요즘 교사를 위한 체육 수업 에듀테크 활용법 : 요즘 체육 수업, 에듀테크로 설계하고 기록되고 성장으로 남는다! | B9: 임우균, 서지원 | C9: 앤써북 | D9: 2026년 02월 | E9: 16800 | F9: 15120 | G9: 19 | H9: 1926 | I9: 2026 | J9: 0 | K9: =(E9-F9)/IF(E9>0,E9,1)
A10: 한 권으로 끝내는 피지컬 AI ROS2 입문+실전(종합편) | B10: 서민우, 전현희, 이현아, 박찬호 | C10: 앤써북 | D10: 2026년 04월 | E10: 25500 | F10: 22950 | G10: 13 | H10: 1680 | I10: 2026 | J10: 0 | K10: =(E10-F10)/IF(E10>0,E10,1)
A11: 교사의 변화가 수업을 바꾼다! : 수업을 바꾸는 교사의 30가지 이야기 | B11: 유승재 | C11: 앤써북 | D11: 2026년 04월 | E11: 17700 | F11: 15930 | G11: 6 | H11: 777 | I11: 2026 | J11: 0 | K11: =(E11-F11)/IF(E11>0,E11,1)
A12: 입상 교사만 아는 아무도 말해주지 않은 디지털교육연구대회 1등급의 비밀 | B12: 강인성 | C12: 앤써북 | D12: 2026년 04월 | E12: 16800 | F12: 15120 | G12: 15 | H12: 732 | I12: 2026 | J12: 0 | K12: =(E12-F12)/IF(E12>0,E12,1)
A13: 2022 개정과 IB 교육 철학을 적용한 초등 개념기반 탐구수업•서술형평가 설계와 실천 | B13: 진경오 | C13: 앤써북 | D13: 2025년 05월 | E13: 21000 | F13: 18900 | G13: 12 | H13: 3546 | I13: 2025 | J13: 0 | K13: =(E13-F13)/IF(E13>0,E13,1)
... A38: 파이썬과 AI 인공지능 카메라를 활용한 자율주행 자동차 | B38: 장문철 | C38: 앤써북 | D38: 2024년 08월 | E38: 25500 | F38: 22950 | G38: 2 | H38: 312 | I38: 2024 | J38: 0 | K38: =(E38-F38)/IF(E38>0,E38,1)
A39: 합계 및 평균 요약 | E39: =AVERAGE(E2:E38) | F39: =AVERAGE(F2:F38) | G39: =SUM(G2:G38) | H39: =SUM(H2:H38) | K39: =AVERAGE(K2:K38)

Sheet 위키북스
A1: 제목 | B1: 저자 | C1: 출판사 | D1: 발행일 | E1: 정가 | F1: 판매가 | G1: 리뷰 수 | H1: 판매지수 | I1: 발행연도 | J1: 발행월 | K1: 할인율
A2: 클로드 코드를 활용한 바이브 코딩 완벽 입문 | B2: 히라카와 토모히데, 최용 | C2: 위키북스 | D2: 2026년 03월 | E2: 26000 | F2: 23400 | G2: 8 | H2: 15519 | I2: 2026 | J2: 0 | K2: =(E2-F2)/IF(E2>0,E2,1)
A3: AI 에이전트 개발 완벽 입문 | B3: 에디 유, 김대규, 조경아, 김현지 | C3: 위키북스 | D3: 2026년 04월 | E3: 42000 | F3: 37800 | G3: 21 | H3: 6285 | I3: 2026 | J3: 0 | K3: =(E3-F3)/IF(E3>0,E3,1)
A4: MCP 실전 활용 & 서버 개발 핵심 가이드 | B4: AI튜터랩 | C4: 위키북스 | D4: 2025년 11월 | E4: 28000 | F4: 25200 | G4: 1 | H4: 2871 | I4: 2025 | J4: 1 | K4: =(E4-F4)/IF(E4>0,E4,1)
A5: UX/UI 디자인 워크숍 with AI | B5: 윤하린 | C5: 위키북스 | D5: 2025년 10월 | E5: 25000 | F5: 22500 | G5: 0 | H5: 840 | I5: 2025 | J5: 1 | K5: =(E5-F5)/IF(E5>0,E5,1)
A6: 나야, 구글 에듀테크. 질문이 답이 되는 제미나이 수업 솔루션 | B6: 장승아, 조원정 | C6: 위키북스 | D6: 2026년 03월 | E6: 24000 | F6: 21600 | G6: 0 | H6: 885 | I6: 2026 | J6: 0 | K6: =(E6-F6)/IF(E6>0,E6,1)
A7: 올라마와 오픈소스 LLM을 활용한 AI 에이전트 개발 입문 | B7: 서영배, 김병규, 임재봉 | C7: 위키북스 | D7: 2026년 01월 | E7: 28000 | F7: 25200 | G7: 2 | H7: 2109 | I7: 2026 | J7: 0 | K7: =(E7-F7)/IF(E7>0,E7,1)
A8: 스프링 AI 인 액션 | B8: 크레이그 월즈, 류광, 307번역랩 | C8: 위키북스 | D8: 2026년 04월 | E8: 32000 | F8: 28800 | G8: 0 | H8: 426 | I8: 2026 | J8: 0 | K8: =(E8-F8)/IF(E8>0,E8,1)
A9: 한 권으로 끝내는 실전 LLM 파인튜닝 | B9: 강다솔 | C9: 위키북스 | D9: 2026년 02월 | E9: 32000 | F9: 28800 | G9: 0 | H9: 1014 | I9: 2026 | J9: 0 | K9: =(E9-F9)/IF(E9>0,E9,1)
A10: OpenAI API와 파이썬으로 나만의 챗GPT 만들기 | B10: 후루카와 쇼이치, 오기와라 유이, 최용 | C10: 위키북스 | D10: 2024년 04월 | E10: 24000 | F10: 21600 | G10: 7 | H10: 366 | I10: 2024 | J10: 0 | K10: =(E10-F10)/IF(E10>0,E10,1)
A11: 랭체인과 랭그래프로 구현하는 RAG·AI 에이전트 실전 입문 | B11: 니시미 마사히로, 요시다 신고, 오시마 유키, 최용 | C11: 위키북스 | D11: 2025년 06월 | E11: 35000 | F11: 31500 | G11: 0 | H11: 1974 | I11: 2025 | J11: 0 | K11: =(E11-F11)/IF(E11>0,E11,1)
A12: 챗GPT는 거들 뿐, 생기부는 내가 쓴다 | B12: 장승아, 조원정 | C12: 위키북스 | D12: 2025년 09월 | E12: 16000 | F12: 14400 | G12: 0 | H12: 2160 | I12: 2025 | J12: 0 | K12: =(E12-F12)/IF(E12>0,E12,1)
A13: 리액트 인터뷰 가이드 | B13: 수디르 조나, 앤드류 바이스덴, 김용찬, 강주희 | C13: 위키북스 | D13: 2024년 08월 | E13: 28000 | F13: 25200 | G13: 5 | H13: 150 | I13: 2024 | J13: 0 | K13: =(E13-F13)/IF(E13>0,E13,1)
... A38: 파이토치와 유니티 ML-Agents로 배우는 강화학습 [응용편] | B38: 민규식, 이현호, 박유민 | C38: 위키북스 | D38: 2025년 01월 | E38: 38000 | F38: 34200 | G38: 1 | H38: 288 | I38: 2025 | J38: 0 | K38: =(E38-F38)/IF(E38>0,E38,1)
A39: 합계 및 평균 요약 | E39: =AVERAGE(E2:E38) | F39: =AVERAGE(F2:F38) | G39: =SUM(G2:G38) | H39: =SUM(H2:H38) | K39: =AVERAGE(K2:K38)

Sheet 기타_출판사
A1: 제목 | B1: 저자 | C1: 출판사 | D1: 발행일 | E1: 정가 | F1: 판매가 | G1: 리뷰 수 | H1: 판매지수 | I1: 발행연도 | J1: 발행월 | K1: 할인율
A2: 클로드 코드로 시작하는 실전 에이전틱 코딩 | B2: Goos Kim | C2: 더 타이즈 | D2: 2026년 05월 | E2: 33000 | F2: 29700 | G2: 11 | H2: 24912 | I2: 2026 | J2: 0 | K2: =(E2-F2)/IF(E2>0,E2,1)
A3: AI 시대의 질문력, 프롬프트 엔지니어링 | B3: 류한석 | C3: 코리아닷컴(Korea.com) | D3: 2025년 08월 | E3: 27000 | F3: 24300 | G3: 61 | H3: 68079 | I3: 2025 | J3: 0 | K3: =(E3-F3)/IF(E3>0,E3,1)
A4: 된다! 캡컷 영상 편집 | B4: 지민이 | C4: 이지스퍼블리싱 | D4: 2026년 05월 | E4: 22000 | F4: 19800 | G4: 17 | H4: 10254 | I4: 2026 | J4: 0 | K4: =(E4-F4)/IF(E4>0,E4,1)
A5: 바쁜 교사를 위한 바로 쓰는 AI | B5: 전소영, 이태화, 조두연 | C5: 사회평론아카데미 | D5: 2026년 04월 | E5: 24000 | F5: 21600 | G5: 17 | H5: 17976 | I5: 2026 | J5: 0 | K5: =(E5-F5)/IF(E5>0,E5,1)
A6: AI 실전 마스터 칼릭스의 프롬프트 디테일 | B6: 칼릭스(손윤석) | C6: 한빛비즈 | D6: 2026년 04월 | E6: 22000 | F6: 19800 | G6: 12 | H6: 9570 | I6: 2026 | J6: 0 | K6: =(E6-F6)/IF(E6>0,E6,1)
A7: 된다! 하루 만에 끝내는 제미나이 활용법 | B7: 권서림 | C7: 이지스퍼블리싱 | D7: 2025년 11월 | E7: 20000 | F7: 18000 | G7: 78 | H7: 73338 | I7: 2025 | J7: 1 | K7: =(E7-F7)/IF(E7>0,E7,1)
A8: 자연은 왜 이토록 단순하면서도 아름다운가 | B8: 로버트 칸, 크리스 퀴그, 박병철 | C8: 알에이치코리아(RHK) | D8: 2026년 04월 | E8: 35000 | F8: 31500 | G8: 12 | H8: 8523 | I8: 2026 | J8: 0 | K8: =(E8-F8)/IF(E8>0,E8,1)
A9: 다시, 소프트웨어 엔지니어 | B9: 네서니얼 슈타, 댄 베가, 박성철 | C9: 책만 | D9: 2026년 05월 | E9: 30000 | F9: 27000 | G9: 0 | H9: 5025 | I9: 2026 | J9: 0 | K9: =(E9-F9)/IF(E9>0,E9,1)
A10: 제미나이 교사 마스터 플랜 (2026년 최신판) | B10: 한민철 | C10: 책바세 | D10: 2026년 04월 | E10: 30000 | F10: 27000 | G10: 26 | H10: 9459 | I10: 2026 | J10: 0 | K10: =(E10-F10)/IF(E10>0,E10,1)
A11: 학교에서 바로 쓰는 제미나이 & 노트북LM | B11: 손성호, 김민, 김상백, 송유미, 박권, 정보 더 보기/감추기, 손성호, 김민, 김상백, 송유미, 박권, 최동욱 | C11: 학교도서관저널 | D11: 2026년 04월 | E11: 19000 | F11: 17100 | G11: 13 | H11: 11061 | I11: 2026 | J11: 0 | K11: =(E11-F11)/IF(E11>0,E11,1)
A12: 일 잘하는 직장인의 AI 활용법 | B12: 김덕중, 김민정, 김인선 | C12: 디지털북스 | D12: 2026년 05월 | E12: 22000 | F12: 19800 | G12: 0 | H12: 3702 | I12: 2026 | J12: 0 | K12: =(E12-F12)/IF(E12>0,E12,1)
A13: 누구나 쉽게 AI 작사 & 작곡 with 생성형 인공지능, 챗GPT, 수노, 유디오 | B13: 현병욱(오땡큐), 신수진 | C13: 시프트 | D13: 2025년 09월 | E13: 20000 | F13: 18000 | G13: 30 | H13: 19986 | I13: 2025 | J13: 0 | K13: =(E13-F13)/IF(E13>0,E13,1)
... A126: 다중 에이전트 시스템을 위한 컨텍스트 엔지니어링 | B126: 데니스 로스먼, 류광, 307번역랩 | C126: 위키아카데미 | D126: 2026년 06월 | E126: 32000 | F126: 28800 | G126: 0 | H126: 120 | I126: 2026 | J126: 0 | K126: =(E126-F126)/IF(E126>0,E126,1)
A127: AI 숏폼 동영상 구글 플로우 FLOW 비오3 VEO3 유튜브 쇼츠 인스타그램 릴스 틱톡 네이버 클립 인공지능 만들기 제작 책 학원강의 교재보다 좋은 USB 강좌 초보 교육 사용법 | C127: 액션미디어 | D127: 2026년 06월 | E127: 39800 | F127: 39800 | G127: 0 | H127: 120 | I127: 2026 | J127: 0 | K127: =(E127-F127)/IF(E127>0,E127,1)
A128: AI 탐구 수업 | B128: 정종수 | C128: 플루토 | D128: 2026년 05월 | E128: 17000 | F128: 15300 | G128: 3 | H128: 489 | I128: 2026 | J128: 0 | K128: =(E128-F128)/IF(E128>0,E128,1)
A129: IT 트렌드 2026 | B129: 김지현 | C129: 크레타 | D129: 2025년 10월 | E129: 20000 | F129: 18000 | G129: 23 | H129: 2787 | I129: 2025 | J129: 1 | K129: =(E129-F129)/IF(E129>0,E129,1)
A130: AI를 활용한 법률문서 작성법 | B130: 김종엽 | C130: (주)박영사 | D130: 2025년 05월 | E130: 27000 | F130: 27000 | G130: 6 | H130: 2304 | I130: 2025 | J130: 0 | K130: =(E130-F130)/IF(E130>0,E130,1)
A131: AX 100배의 법칙 | B131: 황재선 | C131: 좋은습관연구소 | D131: 2025년 06월 | E131: 25000 | F131: 22500 | G131: 4 | H131: 3252 | I131: 2025 | J131: 0 | K131: =(E131-F131)/IF(E131>0,E131,1)
A132: 벡터 데이터베이스 설계와 구축 | B132: 송한림 | C132: 아이리포 | D132: 2025년 03월 | E132: 17800 | F132: 16020 | G132: 7 | H132: 3150 | I132: 2025 | J132: 0 | K132: =(E132-F132)/IF(E132>0,E132,1)
A133: 최고의 프롬프트 엔지니어링 강의 | B133: 김진중 | C133: 리코멘드 | D133: 2024년 06월 | E133: 24000 | F133: 21600 | G133: 18 | H133: 1944 | I133: 2024 | J133: 0 | K133: =(E133-F133)/IF(E133>0,E133,1)
A134: 학업과 취업을 위한 제미나이 노트북LM으로 무엇이든 만들 수 있다 | B134: 전다희, 황우현 | C134: 광문각출판미디어 | D134: 2026년 02월 | E134: 22000 | F134: 22000 | G134: 15 | H134: 564 | I134: 2026 | J134: 0 | K134: =(E134-F134)/IF(E134>0,E134,1)
A135: Dify, 코딩 없이 AI 앱 개발의 시작 | B135: 멀티코어, 조준희, 강장묵, 이상한, 윤철희 | C135: 프리렉 | D135: 2025년 12월 | E135: 25000 | F135: 22500 | G135: 4 | H135: 660 | I135: 2025 | J135: 1 | K135: =(E135-F135)/IF(E135>0,E135,1)
A136: 비개발자도 클로드 코드로 쉽게 만드는 AI 웹 서비스 | B136: 최원재 | C136: 위즈앤북 | D136: 2026년 05월 | E136: 25000 | F136: 22500 | G136: 0 | H136: 522 | I136: 2026 | J136: 0 | K136: =(E136-F136)/IF(E136>0,E136,1)
A137: 된다! 하루 만에 만드는 AI 사진 & 이미지 | B137: 김원석 | C137: 이지스퍼블리싱 | D137: 2025년 08월 | E137: 17800 | F137: 16020 | G137: 40 | H137: 3912 | I137: 2025 | J137: 0 | K137: =(E137-F137)/IF(E137>0,E137,1)
A138: 한 권으로 끝내는 AI 자동화 | B138: 최재용, 이요셉, 이신우, 최금선, 박경희, 정보 더 보기/감추기, 최재용, 이요셉, 이신우, 최금선, 박경희, 유미경, 한주은, 오영주, 정은진, 김진수 | C138: 두온교육(주) | D138: 2026년 05월 | E138: 22000 | F138: 19800 | G138: 0 | H138: 246 | I138: 2026 | J138: 0 | K138: =(E138-F138)/IF(E138>0,E138,1)
A139: AI 시대 엄마가 먼저 알아야 할 최상위 공부법 | B139: 오주연, 김지예, 김현아 | C139: 한빛비즈 | D139: 2026년 03월 | E139: 22000 | F139: 19800 | G139: 16 | H139: 1242 | I139: 2026 | J139: 0 | K139: =(E139-F139)/IF(E139>0,E139,1)
... A299: 김변호사의 스마트한 AI 활용법 | B299: 김변호사 팀 | C299: (주)박영사 | D299: 2025년 03월 | E299: 18000 | F299: 18000 | G299: 1 | H299: 1320 | I299: 2025 | J299: 0 | K299: =(E299-F299)/IF(E299>0,E299,1)
A300: Data AI | C300: 호산나 | D300: 2026년 05월 | E300: 35000 | F300: 33250 | G300: 6 | H300: 168 | I300: 2026 | J300: 0 | K300: =(E300-F300)/IF(E300>0,E300,1)
A301: AI 시대 사고의 정석 - 유추 | B301: 이진화 | C301: 지식과감성# | D301: 2026년 05월 | E301: 23000 | F301: 20700 | G301: 1 | H301: 168 | I301: 2026 | J301: 0 | K301: =(E301-F301)/IF(E301>0,E301,1)
A302: AI를 직원처럼 쓰는 마케팅 자동화 시스템 | B302: 이종구, 이정화, 김회균, 손정화 | C302: 디지털콘텐츠그룹 | D302: 2026년 05월 | E302: 24000 | F302: 21600 | G302: 0 | H302: 168 | I302: 2026 | J302: 0 | K302: =(E302-F302)/IF(E302>0,E302,1)
A303: 말로 만드는 창업의 시대 | B303: 심재우, 선웅규 | C303: 진한엠앤비 | D303: 2026년 05월 | E303: 23000 | F303: 21850 | G303: 0 | H303: 192 | I303: 2026 | J303: 0 | K303: =(E303-F303)/IF(E303>0,E303,1)
A304: AI로 쉽게 자기역사 쓰기 | B304: 진순희 | C304: 씽크스마트 | D304: 2026년 03월 | E304: 17000 | F304: 15300 | G304: 19 | H304: 186 | I304: 2026 | J304: 0 | K304: =(E304-F304)/IF(E304>0,E304,1)
A305: 수학으로 이해하는 기초강화학습 | B305: 이동환 | C305: 가우스출판 | D305: 2025년 03월 | E305: 35000 | F305: 31500 | G305: 0 | H305: 198 | I305: 2025 | J305: 0 | K305: =(E305-F305)/IF(E305>0,E305,1)
A306: 핵심 딥러닝 입문: RNN, LSTM, GRU, VAE, GAN 구현 | B306: 아즈마 유키나가, 최재원, 장건희 | C306: 책만 | D306: 2020년 12월 | E306: 28000 | F306: 25200 | G306: 4 | H306: 198 | I306: 2020 | J306: 1 | K306: =(E306-F306)/IF(E306>0,E306,1)
A307: 인공지능과 국제정치 전환 | B307: 김상배, 이원태, 유인태, 이승주, 윤정현, 정보 더 보기/감추기, 김상배, 이원태, 유인태, 이승주, 윤정현, 이종진, 정헌주, 윤대엽, 이수연, 송태은 | C307: 한울아카데미 | D307: 2025년 10월 | E307: 39000 | F307: 39000 | G307: 0 | H307: 204 | I307: 2025 | J307: 1 | K307: =(E307-F307)/IF(E307>0,E307,1)
A308: AI 코드, 디코딩: AI 시대, 개발자의 연봉과 가치를 증명하는 코드 리터러시 | B308: 엄경률 | C308: BOOKK(부크크) | D308: 2025년 07월 | E308: 28900 | F308: 28900 | G308: 0 | H308: 192 | I308: 2025 | J308: 0 | K308: =(E308-F308)/IF(E308>0,E308,1)
A309: 초보로 | B309: 김홍순, 권현중, 김민주, 오승영, 박지숙 | C309: 홍릉 | D309: 2026년 03월 | E309: 19000 | F309: 19000 | G309: 1 | H309: 144 | I309: 2026 | J309: 0 | K309: =(E309-F309)/IF(E309>0,E309,1)
A310: 데이터 그랩 | B310: 울리세스 알리 메히아스, 닉 콜드리, 공경희 | C310: 영림카디널 | D310: 2024년 06월 | E310: 21000 | F310: 18900 | G310: 15 | H310: 126 | I310: 2024 | J310: 0 | K310: =(E310-F310)/IF(E310>0,E310,1)
A311: 테크니컬 리더 | B311: 제럴드 M. 와인버그 | C311: 인사이트(insight) | D311: 2013년 01월 | E311: 18000 | F311: 16200 | G311: 4 | H311: 156 | I311: 2013 | J311: 0 | K311: =(E311-F311)/IF(E311>0,E311,1)
...
